2020-09-22 16:38:14.519824: I tensorflow/core/platform/cpu_feature_guard.cc:141] Your CPU supports instructions that this TensorFlow binary was not compiled to use: AVX2 FMA
2020-09-22 16:38:14.722116: I tensorflow/core/common_runtime/gpu/gpu_device.cc:1432] Found device 0 with properties: 
name: GeForce GTX 1080 major: 6 minor: 1 memoryClockRate(GHz): 1.7335
pciBusID: 0000:03:00.0
totalMemory: 7.93GiB freeMemory: 7.81GiB
2020-09-22 16:38:14.722150: I tensorflow/core/common_runtime/gpu/gpu_device.cc:1511] Adding visible gpu devices: 0
2020-09-22 16:38:14.962683: I tensorflow/core/common_runtime/gpu/gpu_device.cc:982] Device interconnect StreamExecutor with strength 1 edge matrix:
2020-09-22 16:38:14.962720: I tensorflow/core/common_runtime/gpu/gpu_device.cc:988]      0 
2020-09-22 16:38:14.962727: I tensorflow/core/common_runtime/gpu/gpu_device.cc:1001] 0:   N 
2020-09-22 16:38:14.962814: I tensorflow/core/common_runtime/gpu/gpu_device.cc:1115] Created TensorFlow device (/job:localhost/replica:0/task:0/device:GPU:0 with 7534 MB memory) -> physical GPU (device: 0, name: GeForce GTX 1080, pci bus id: 0000:03:00.0, compute capability: 6.1)
WARNING:tensorflow:From /home/ramzimissaoui/missions/off/local/models_test/TIES-2.0/python/iterators/table_adjacency_parsing_iterator.py:67: start_queue_runners (from tensorflow.python.training.queue_runner_impl) is deprecated and will be removed in a future version.
Instructions for updating:
To construct input pipelines, use the `tf.data` module.
WARNING:tensorflow:`tf.train.start_queue_runners()` was called when no queue runners were defined. You can safely remove the call to this deprecated function.
Traceback (most recent call last):
  File "/home/ramzimissaoui/.local/lib/python3.6/site-packages/tensorflow/python/client/session.py", line 1334, in _do_call
    return fn(*args)
  File "/home/ramzimissaoui/.local/lib/python3.6/site-packages/tensorflow/python/client/session.py", line 1319, in _run_fn
    options, feed_dict, fetch_list, target_list, run_metadata)
  File "/home/ramzimissaoui/.local/lib/python3.6/site-packages/tensorflow/python/client/session.py", line 1407, in _call_tf_sessionrun
    run_metadata)
tensorflow.python.framework.errors_impl.DataLossError: inflate() failed with error -3: incorrect header check
	 [[{{node IteratorGetNext_1}} = IteratorGetNext[output_shapes=[[?,4500], [?,27000], [?,1049088], [?,4], [?,810000], [?,810000], [?,810000]], output_types=[DT_FLOAT, DT_INT64, DT_FLOAT, DT_FLOAT, DT_INT64, DT_INT64, DT_INT64], _device="/job:localhost/replica:0/task:0/device:CPU:0"](OneShotIterator_1)]]
	 [[{{node IteratorGetNext_1/_9}} = _Recv[client_terminated=false, recv_device="/job:localhost/replica:0/task:0/device:GPU:0", send_device="/job:localhost/replica:0/task:0/device:CPU:0", send_device_incarnation=1, tensor_name="edge_11_IteratorGetNext_1", tensor_type=DT_INT64, _device="/job:localhost/replica:0/task:0/device:GPU:0"]()]]

During handling of the above exception, another exception occurred:

Traceback (most recent call last):
  File "bin/iterate/table_adjacency_parsing.py", line 31, in <module>
    trainer.train()
  File "/home/ramzimissaoui/missions/off/local/models_test/TIES-2.0/python/iterators/table_adjacency_parsing_iterator.py", line 78, in train
    model.sanity_preplot(sess, summary_writer)
  File "/home/ramzimissaoui/missions/off/local/models_test/TIES-2.0/python/models/basic_model.py", line 460, in sanity_preplot
    feeds = sess.run(self.validation_feeds)
  File "/home/ramzimissaoui/.local/lib/python3.6/site-packages/tensorflow/python/client/session.py", line 929, in run
    run_metadata_ptr)
  File "/home/ramzimissaoui/.local/lib/python3.6/site-packages/tensorflow/python/client/session.py", line 1152, in _run
    feed_dict_tensor, options, run_metadata)
  File "/home/ramzimissaoui/.local/lib/python3.6/site-packages/tensorflow/python/client/session.py", line 1328, in _do_run
    run_metadata)
  File "/home/ramzimissaoui/.local/lib/python3.6/site-packages/tensorflow/python/client/session.py", line 1348, in _do_call
    raise type(e)(node_def, op, message)
tensorflow.python.framework.errors_impl.DataLossError: inflate() failed with error -3: incorrect header check
	 [[node IteratorGetNext_1 (defined at /home/ramzimissaoui/missions/off/local/models_test/TIES-2.0/python/readers/image_words_reader.py:67)  = IteratorGetNext[output_shapes=[[?,4500], [?,27000], [?,1049088], [?,4], [?,810000], [?,810000], [?,810000]], output_types=[DT_FLOAT, DT_INT64, DT_FLOAT, DT_FLOAT, DT_INT64, DT_INT64, DT_INT64], _device="/job:localhost/replica:0/task:0/device:CPU:0"](OneShotIterator_1)]]
	 [[{{node IteratorGetNext_1/_9}} = _Recv[client_terminated=false, recv_device="/job:localhost/replica:0/task:0/device:GPU:0", send_device="/job:localhost/replica:0/task:0/device:CPU:0", send_device_incarnation=1, tensor_name="edge_11_IteratorGetNext_1", tensor_type=DT_INT64, _device="/job:localhost/replica:0/task:0/device:GPU:0"]()]]

Caused by op 'IteratorGetNext_1', defined at:
  File "bin/iterate/table_adjacency_parsing.py", line 31, in <module>
    trainer.train()
  File "/home/ramzimissaoui/missions/off/local/models_test/TIES-2.0/python/iterators/table_adjacency_parsing_iterator.py", line 48, in train
    model.initialize(training=True)
  File "/home/ramzimissaoui/missions/off/local/models_test/TIES-2.0/python/models/basic_model.py", line 73, in initialize
    self.validation_feeds = self.validation_reader.get_feeds()
  File "/home/ramzimissaoui/missions/off/local/models_test/TIES-2.0/python/readers/image_words_reader.py", line 67, in get_feeds
    vertex_features, vertex_text, image, global_features, adj_cells, adj_rows, adj_cols = iterator.get_next()
  File "/home/ramzimissaoui/.local/lib/python3.6/site-packages/tensorflow/python/data/ops/iterator_ops.py", line 421, in get_next
    name=name)), self._output_types,
  File "/home/ramzimissaoui/.local/lib/python3.6/site-packages/tensorflow/python/ops/gen_dataset_ops.py", line 2069, in iterator_get_next
    output_shapes=output_shapes, name=name)
  File "/home/ramzimissaoui/.local/lib/python3.6/site-packages/tensorflow/python/framework/op_def_library.py", line 787, in _apply_op_helper
    op_def=op_def)
  File "/home/ramzimissaoui/.local/lib/python3.6/site-packages/tensorflow/python/util/deprecation.py", line 488, in new_func
    return func(*args, **kwargs)
  File "/home/ramzimissaoui/.local/lib/python3.6/site-packages/tensorflow/python/framework/ops.py", line 3274, in create_op
    op_def=op_def)
  File "/home/ramzimissaoui/.local/lib/python3.6/site-packages/tensorflow/python/framework/ops.py", line 1770, in __init__
    self._traceback = tf_stack.extract_stack()

DataLossError (see above for traceback): inflate() failed with error -3: incorrect header check
	 [[node IteratorGetNext_1 (defined at /home/ramzimissaoui/missions/off/local/models_test/TIES-2.0/python/readers/image_words_reader.py:67)  = IteratorGetNext[output_shapes=[[?,4500], [?,27000], [?,1049088], [?,4], [?,810000], [?,810000], [?,810000]], output_types=[DT_FLOAT, DT_INT64, DT_FLOAT, DT_FLOAT, DT_INT64, DT_INT64, DT_INT64], _device="/job:localhost/replica:0/task:0/device:CPU:0"](OneShotIterator_1)]]
	 [[{{node IteratorGetNext_1/_9}} = _Recv[client_terminated=false, recv_device="/job:localhost/replica:0/task:0/device:GPU:0", send_device="/job:localhost/replica:0/task:0/device:CPU:0", send_device_incarnation=1, tensor_name="edge_11_IteratorGetNext_1", tensor_type=DT_INT64, _device="/job:localhost/replica:0/task:0/device:GPU:0"]()]]

